[2023-06-12T12:17:04.923+0000] {taskinstance.py:1103} INFO - Dependencies all met for dep_context=non-requeueable deps ti=<TaskInstance: blob_sensor_dag.wait_for_blob manual__2023-06-12T12:17:01.312040+00:00 [queued]>
[2023-06-12T12:17:04.929+0000] {taskinstance.py:1103} INFO - Dependencies all met for dep_context=requeueable deps ti=<TaskInstance: blob_sensor_dag.wait_for_blob manual__2023-06-12T12:17:01.312040+00:00 [queued]>
[2023-06-12T12:17:04.930+0000] {taskinstance.py:1308} INFO - Starting attempt 1 of 1
[2023-06-12T12:17:04.947+0000] {taskinstance.py:1327} INFO - Executing <Task(WasbBlobSensor): wait_for_blob> on 2023-06-12 12:17:01.312040+00:00
[2023-06-12T12:17:04.950+0000] {standard_task_runner.py:57} INFO - Started process 5096 to run task
[2023-06-12T12:17:04.954+0000] {standard_task_runner.py:84} INFO - Running: ['airflow', 'tasks', 'run', 'blob_sensor_dag', 'wait_for_blob', 'manual__2023-06-12T12:17:01.312040+00:00', '--job-id', '21', '--raw', '--subdir', 'DAGS_FOLDER/blob_sensor_dag.py', '--cfg-path', '/tmp/tmprk0und8b']
[2023-06-12T12:17:04.955+0000] {standard_task_runner.py:85} INFO - Job 21: Subtask wait_for_blob
[2023-06-12T12:17:05.002+0000] {task_command.py:410} INFO - Running <TaskInstance: blob_sensor_dag.wait_for_blob manual__2023-06-12T12:17:01.312040+00:00 [running]> on host ubuntu.thbnzb0d3dmuziyfg2t53bofqb.tx.internal.cloudapp.net
[2023-06-12T12:17:05.069+0000] {taskinstance.py:1545} INFO - Exporting env vars: AIRFLOW_CTX_DAG_OWNER='airflow' AIRFLOW_CTX_DAG_ID='blob_sensor_dag' AIRFLOW_CTX_TASK_ID='wait_for_blob' AIRFLOW_CTX_EXECUTION_DATE='2023-06-12T12:17:01.312040+00:00' AIRFLOW_CTX_TRY_NUMBER='1' AIRFLOW_CTX_DAG_RUN_ID='manual__2023-06-12T12:17:01.312040+00:00'
[2023-06-12T12:17:05.071+0000] {wasb.py:70} INFO - Poking for blob: checksum.txt
 in wasb://input
[2023-06-12T12:17:05.076+0000] {base.py:73} INFO - Using connection ID 'wasb_default' for task execution.
[2023-06-12T12:17:05.077+0000] {environment.py:107} INFO - No environment configuration found.
[2023-06-12T12:17:05.080+0000] {managed_identity.py:94} INFO - ManagedIdentityCredential will use IMDS
[2023-06-12T12:17:05.081+0000] {wasb.py:215} INFO - Using DefaultAzureCredential as credential
[2023-06-12T12:17:05.283+0000] {chained.py:110} WARNING - DefaultAzureCredential failed to retrieve a token from the included credentials.
Attempted credentials:
	EnvironmentCredential: EnvironmentCredential authentication unavailable. Environment variables are not fully configured.
Visit https://aka.ms/azsdk/python/identity/environmentcredential/troubleshoot to troubleshoot this issue.
	ManagedIdentityCredential: ManagedIdentityCredential authentication unavailable. The requested identity has not been assigned to this resource.
	SharedTokenCacheCredential: SharedTokenCacheCredential authentication unavailable. No accounts were found in the cache.
	AzureCliCredential: Azure CLI not found on path
	AzurePowerShellCredential: PowerShell is not installed
	AzureDeveloperCliCredential: Azure Developer CLI could not be found. Please visit https://aka.ms/azure-dev for installation instructions and then,once installed, authenticate to your Azure account using 'azd auth login'.
To mitigate this issue, please refer to the troubleshooting guidelines here at https://aka.ms/azsdk/python/identity/defaultazurecredential/troubleshoot.
[2023-06-12T12:17:23.500+0000] {chained.py:110} WARNING - DefaultAzureCredential failed to retrieve a token from the included credentials.
Attempted credentials:
	EnvironmentCredential: EnvironmentCredential authentication unavailable. Environment variables are not fully configured.
Visit https://aka.ms/azsdk/python/identity/environmentcredential/troubleshoot to troubleshoot this issue.
	ManagedIdentityCredential: ManagedIdentityCredential authentication unavailable. The requested identity has not been assigned to this resource.
	SharedTokenCacheCredential: SharedTokenCacheCredential authentication unavailable. No accounts were found in the cache.
	AzureCliCredential: Azure CLI not found on path
	AzurePowerShellCredential: PowerShell is not installed
	AzureDeveloperCliCredential: Azure Developer CLI could not be found. Please visit https://aka.ms/azure-dev for installation instructions and then,once installed, authenticate to your Azure account using 'azd auth login'.
To mitigate this issue, please refer to the troubleshooting guidelines here at https://aka.ms/azsdk/python/identity/defaultazurecredential/troubleshoot.
[2023-06-12T12:17:47.269+0000] {chained.py:110} WARNING - DefaultAzureCredential failed to retrieve a token from the included credentials.
Attempted credentials:
	EnvironmentCredential: EnvironmentCredential authentication unavailable. Environment variables are not fully configured.
Visit https://aka.ms/azsdk/python/identity/environmentcredential/troubleshoot to troubleshoot this issue.
	ManagedIdentityCredential: ManagedIdentityCredential authentication unavailable. The requested identity has not been assigned to this resource.
	SharedTokenCacheCredential: SharedTokenCacheCredential authentication unavailable. No accounts were found in the cache.
	AzureCliCredential: Azure CLI not found on path
	AzurePowerShellCredential: PowerShell is not installed
	AzureDeveloperCliCredential: Azure Developer CLI could not be found. Please visit https://aka.ms/azure-dev for installation instructions and then,once installed, authenticate to your Azure account using 'azd auth login'.
To mitigate this issue, please refer to the troubleshooting guidelines here at https://aka.ms/azsdk/python/identity/defaultazurecredential/troubleshoot.
[2023-06-12T12:18:29.090+0000] {chained.py:110} WARNING - DefaultAzureCredential failed to retrieve a token from the included credentials.
Attempted credentials:
	EnvironmentCredential: EnvironmentCredential authentication unavailable. Environment variables are not fully configured.
Visit https://aka.ms/azsdk/python/identity/environmentcredential/troubleshoot to troubleshoot this issue.
	ManagedIdentityCredential: ManagedIdentityCredential authentication unavailable. The requested identity has not been assigned to this resource.
	SharedTokenCacheCredential: SharedTokenCacheCredential authentication unavailable. No accounts were found in the cache.
	AzureCliCredential: Azure CLI not found on path
	AzurePowerShellCredential: PowerShell is not installed
	AzureDeveloperCliCredential: Azure Developer CLI could not be found. Please visit https://aka.ms/azure-dev for installation instructions and then,once installed, authenticate to your Azure account using 'azd auth login'.
To mitigate this issue, please refer to the troubleshooting guidelines here at https://aka.ms/azsdk/python/identity/defaultazurecredential/troubleshoot.
[2023-06-12T12:18:29.091+0000] {taskinstance.py:1824} ERROR - Task failed with exception
Traceback (most recent call last):
  File "/home/satyam/.local/lib/python3.8/site-packages/airflow/providers/microsoft/azure/sensors/wasb.py", line 79, in execute
    super().execute(context=context)
  File "/usr/local/lib/python3.8/dist-packages/airflow/sensors/base.py", line 225, in execute
    raise e
  File "/usr/local/lib/python3.8/dist-packages/airflow/sensors/base.py", line 212, in execute
    poke_return = self.poke(context)
  File "/home/satyam/.local/lib/python3.8/site-packages/airflow/providers/microsoft/azure/sensors/wasb.py", line 72, in poke
    return hook.check_for_blob(self.container_name, self.blob_name, **self.check_options)
  File "/home/satyam/.local/lib/python3.8/site-packages/airflow/providers/microsoft/azure/hooks/wasb.py", line 250, in check_for_blob
    self._get_blob_client(container_name, blob_name).get_blob_properties(**kwargs)
  File "/home/satyam/.local/lib/python3.8/site-packages/azure/core/tracing/decorator.py", line 76, in wrapper_use_tracer
    return func(*args, **kwargs)
  File "/home/satyam/.local/lib/python3.8/site-packages/azure/storage/blob/_blob_client.py", line 1332, in get_blob_properties
    process_storage_error(error)
  File "/home/satyam/.local/lib/python3.8/site-packages/azure/storage/blob/_shared/response_handlers.py", line 97, in process_storage_error
    raise storage_error
  File "/home/satyam/.local/lib/python3.8/site-packages/azure/storage/blob/_blob_client.py", line 1322, in get_blob_properties
    blob_props = self._client.blob.get_properties(
  File "/home/satyam/.local/lib/python3.8/site-packages/azure/core/tracing/decorator.py", line 76, in wrapper_use_tracer
    return func(*args, **kwargs)
  File "/home/satyam/.local/lib/python3.8/site-packages/azure/storage/blob/_generated/operations/_blob_operations.py", line 1874, in get_properties
    pipeline_response = self._client._pipeline.run(  # type: ignore # pylint: disable=protected-access
  File "/home/satyam/.local/lib/python3.8/site-packages/azure/core/pipeline/_base.py", line 202, in run
    return first_node.send(pipeline_request)
  File "/home/satyam/.local/lib/python3.8/site-packages/azure/core/pipeline/_base.py", line 70, in send
    response = self.next.send(request)
  File "/home/satyam/.local/lib/python3.8/site-packages/azure/core/pipeline/_base.py", line 70, in send
    response = self.next.send(request)
  File "/home/satyam/.local/lib/python3.8/site-packages/azure/core/pipeline/_base.py", line 70, in send
    response = self.next.send(request)
  [Previous line repeated 2 more times]
  File "/home/satyam/.local/lib/python3.8/site-packages/azure/core/pipeline/policies/_redirect.py", line 156, in send
    response = self.next.send(request)
  File "/home/satyam/.local/lib/python3.8/site-packages/azure/core/pipeline/_base.py", line 70, in send
    response = self.next.send(request)
  File "/home/satyam/.local/lib/python3.8/site-packages/azure/storage/blob/_shared/policies.py", line 546, in send
    raise err
  File "/home/satyam/.local/lib/python3.8/site-packages/azure/storage/blob/_shared/policies.py", line 520, in send
    response = self.next.send(request)
  File "/home/satyam/.local/lib/python3.8/site-packages/azure/core/pipeline/_base.py", line 70, in send
    response = self.next.send(request)
  File "/home/satyam/.local/lib/python3.8/site-packages/azure/core/pipeline/_base.py", line 70, in send
    response = self.next.send(request)
  File "/home/satyam/.local/lib/python3.8/site-packages/azure/core/pipeline/policies/_authentication.py", line 111, in send
    self.on_request(request)
  File "/home/satyam/.local/lib/python3.8/site-packages/azure/core/pipeline/policies/_authentication.py", line 90, in on_request
    self._token = self._credential.get_token(*self._scopes)
  File "/home/satyam/.local/lib/python3.8/site-packages/azure/identity/_credentials/default.py", line 214, in get_token
    return super(DefaultAzureCredential, self).get_token(*scopes, **kwargs)
  File "/home/satyam/.local/lib/python3.8/site-packages/azure/identity/_credentials/chained.py", line 111, in get_token
    raise ClientAuthenticationError(message=message)
azure.core.exceptions.ClientAuthenticationError: DefaultAzureCredential failed to retrieve a token from the included credentials.
Attempted credentials:
	EnvironmentCredential: EnvironmentCredential authentication unavailable. Environment variables are not fully configured.
Visit https://aka.ms/azsdk/python/identity/environmentcredential/troubleshoot to troubleshoot this issue.
	ManagedIdentityCredential: ManagedIdentityCredential authentication unavailable. The requested identity has not been assigned to this resource.
	SharedTokenCacheCredential: SharedTokenCacheCredential authentication unavailable. No accounts were found in the cache.
	AzureCliCredential: Azure CLI not found on path
	AzurePowerShellCredential: PowerShell is not installed
	AzureDeveloperCliCredential: Azure Developer CLI could not be found. Please visit https://aka.ms/azure-dev for installation instructions and then,once installed, authenticate to your Azure account using 'azd auth login'.
To mitigate this issue, please refer to the troubleshooting guidelines here at https://aka.ms/azsdk/python/identity/defaultazurecredential/troubleshoot.
[2023-06-12T12:18:29.104+0000] {taskinstance.py:1345} INFO - Marking task as FAILED. dag_id=blob_sensor_dag, task_id=wait_for_blob, execution_date=20230612T121701, start_date=20230612T121704, end_date=20230612T121829
[2023-06-12T12:18:29.127+0000] {standard_task_runner.py:104} ERROR - Failed to execute job 21 for task wait_for_blob (DefaultAzureCredential failed to retrieve a token from the included credentials.
Attempted credentials:
	EnvironmentCredential: EnvironmentCredential authentication unavailable. Environment variables are not fully configured.
Visit https://aka.ms/azsdk/python/identity/environmentcredential/troubleshoot to troubleshoot this issue.
	ManagedIdentityCredential: ManagedIdentityCredential authentication unavailable. The requested identity has not been assigned to this resource.
	SharedTokenCacheCredential: SharedTokenCacheCredential authentication unavailable. No accounts were found in the cache.
	AzureCliCredential: Azure CLI not found on path
	AzurePowerShellCredential: PowerShell is not installed
	AzureDeveloperCliCredential: Azure Developer CLI could not be found. Please visit https://aka.ms/azure-dev for installation instructions and then,once installed, authenticate to your Azure account using 'azd auth login'.
To mitigate this issue, please refer to the troubleshooting guidelines here at https://aka.ms/azsdk/python/identity/defaultazurecredential/troubleshoot.; 5096)
[2023-06-12T12:18:29.158+0000] {local_task_job_runner.py:225} INFO - Task exited with return code 1
[2023-06-12T12:18:29.176+0000] {taskinstance.py:2651} INFO - 0 downstream tasks scheduled from follow-on schedule check
